Workbook
Name BusinessName: 'Settings'!$B$4
Name Currency: 'Settings'!$B$11
Name ServiceList: 'Settings'!$A$22:$A$35
Name SofaServiceList: 'Settings'!$A$39:$A$48
Name LaundryServiceList: 'Settings'!$A$52:$A$61
Name SpecializedServiceList: 'Settings'!$A$65:$A$69
Name HousehelpCategoryList: 'Settings'!$A$73:$A$76
Name PaymentMethods: 'Settings'!$A$80:$A$84
Name OrderStatuses: 'Settings'!$A$88:$A$92
Name PaymentStatuses: 'Settings'!$A$96:$A$98
Name ExpenseCategories: 'Settings'!$A$102:$A$112
Name HousehelpStatuses: 'Settings'!$A$116:$A$120
Name ContractStatuses: 'Settings'!$A$124:$A$127
Name PlacementStatuses: 'Settings'!$A$131:$A$137
Name ComplaintStatuses: 'Settings'!$A$141:$A$145
Name ComplaintTypes: 'Settings'!$A$149:$A$157
Name EmployeeWorkerTypes: 'Settings'!$A$161:$A$163
Name SeverityLevels: 'Settings'!$A$167:$A$169
Name PaymentFrequencies: 'Settings'!$A$173:$A$174
Name AttendanceStatuses: 'Settings'!$A$178:$A$181

Sheet Settings
A1: DEE CLEANERS — SETTINGS
A2: Edit values below, or manage them from the app: Services / Settings pages.
A3: Setting | B3: Value
A4: Business Name | B4: Dee Cleaners
A5: Phone 1 | B5: +255 693 806 051
A6: Phone 2 | B6: +255 762 292 439
A7: Email | B7: deecleanerscleaningservices@gmail.com
A8: Address | B8: Magomeni, Mikumi
A9: Website
A10: Social Media
A11: Currency | B11: TZS
A12: Default Transport Policy | B12: Customer pays transport fees (Transport fees ni juu ya mteja)
A13: Room Pricing Note | B13: Bei zinapungua au Kuongezeka kulingana na ukubwa wa chumba (prices may decrease or increase depending on room size)
A14: Live-in Working Hours | B14: 5:00 a.m. - 6:30 p.m.
A15: Minimum Work Duration (months) | B15: 3
A16: Agency Fee Note | B16: One-time agency fee paid by the employer upon contract initiation
A17: Payment Policy Note | B17: All househelp service payments are made directly to Dee Cleaners, which handles salary disbursement
A18: Logo Reference | B18: assets/dee_cleaners_logo/dee_cleaners_logo.png
A20: CLEANING SERVICES
A21: Name | B21: Min Price | C21: Max Price | D21: Category | E21: Active | F21: Description
A22: Toilet Cleaning | B22: 30000 | C22: 40000 | D22: Cleaning | E22: Yes
A23: Kitchen Cleaning | B23: 50000 | C23: 150000 | D23: Cleaning | E23: Yes
A24: Chumba Kimoja (One Room) | B24: 50000 | C24: 50000 | D24: Cleaning | E24: Yes
A25: Window Cleaning | B25: 15000 | C25: 20000 | D25: Cleaning | E25: Yes
A26: Sitting Room & 2 Bedrooms | B26: 150000 | C26: 150000 | D26: Empty Rooms | E26: Yes
A27: Sitting Room & 3 Bedrooms | B27: 200000 | C27: 200000 | D27: Empty Rooms | E27: Yes
A28: Sitting Room & 4 Bedrooms | B28: 250000 | C28: 250000 | D28: Empty Rooms | E28: Yes
A29: Sitting Room & 5 Bedrooms | B29: 350000 | C29: 350000 | D29: Empty Rooms | E29: Yes
A30: Sitting Room & 6 Bedrooms | B30: 450000 | C30: 450000 | D30: Empty Rooms | E30: Yes
A31: Sitting Room & 2 Bedrooms | B31: 200000 | C31: 200000 | D31: Rooms With Furniture Cleaning | E31: Yes
A32: Sitting Room & 3 Bedrooms | B32: 250000 | C32: 250000 | D32: Rooms With Furniture Cleaning | E32: Yes
A33: Sitting Room & 4 Bedrooms | B33: 300000 | C33: 300000 | D33: Rooms With Furniture Cleaning | E33: Yes
... A35: Sitting Room & 6 Bedrooms | B35: 450000 | C35: 450000 | D35: Rooms With Furniture Cleaning | E35: Yes
A37: SOFA SERVICES
A38: Name | B38: Min Price | C38: Max Price | D38: Active
A39: One Seater Sofa Set | B39: 15000 | C39: 15000 | D39: Yes
A40: Two Seater Sofa Set | B40: 30000 | C40: 30000 | D40: Yes
A41: Three Seater Sofa Set | B41: 45000 | C41: 45000 | D41: Yes
A42: Four Seater Sofa Set | B42: 60000 | C42: 60000 | D42: Yes
A43: Five Seater Sofa Set | B43: 75000 | C43: 75000 | D43: Yes
...

Sheet Orders
A1: DEE CLEANERS — ORDERS
A2: Grey columns are formulas — do not edit them. Fill white columns or use the app. Transport fee is paid by the customer.
A3: Order ID | B3: Date | C3: Customer Name | D3: Phone | E3: Email | F3: Service | G3: Description | H3: Quantity | I3: Unit Price | J3: Discount | K3: Total* | L3: Amount Paid | M3: Balance* | N3: Payment Status* | O3: Order Status | P3: Transport Fee | Q3: Direct Expense | R3: Net Service Profit* | S3: Notes | T3: Line Items JSON | U3: Unique Customer Helper*
A4: =IF(B4="","",TEXT(ROW()-3,"""DC-""0000")) | K4: =IF(B4="","",MAX(0,IFERROR(I4,0)*IFERROR(H4,0)-IFERROR(J4,0))) | M4: =IF(B4="","",MAX(0,K4-L4)) | N4: =IF(B4="","",IF(L4>=K4,"Paid",IF(L4>0,"Partial","Unpaid"))) | R4: =IF(B4="","",IFERROR(K4,0)+IFERROR(P4,0)-IFERROR(Q4,0)) | U4: =IF(B4="","",TRIM(LOWER(C4)&"|"&LOWER(D4)))
A5: =IF(B5="","",TEXT(ROW()-3,"""DC-""0000")) | K5: =IF(B5="","",MAX(0,IFERROR(I5,0)*IFERROR(H5,0)-IFERROR(J5,0))) | M5: =IF(B5="","",MAX(0,K5-L5)) | N5: =IF(B5="","",IF(L5>=K5,"Paid",IF(L5>0,"Partial","Unpaid"))) | R5: =IF(B5="","",IFERROR(K5,0)+IFERROR(P5,0)-IFERROR(Q5,0)) | U5: =IF(B5="","",TRIM(LOWER(C5)&"|"&LOWER(D5)))
A6: =IF(B6="","",TEXT(ROW()-3,"""DC-""0000")) | K6: =IF(B6="","",MAX(0,IFERROR(I6,0)*IFERROR(H6,0)-IFERROR(J6,0))) | M6: =IF(B6="","",MAX(0,K6-L6)) | N6: =IF(B6="","",IF(L6>=K6,"Paid",IF(L6>0,"Partial","Unpaid"))) | R6: =IF(B6="","",IFERROR(K6,0)+IFERROR(P6,0)-IFERROR(Q6,0)) | U6: =IF(B6="","",TRIM(LOWER(C6)&"|"&LOWER(D6)))
A7: =IF(B7="","",TEXT(ROW()-3,"""DC-""0000")) | K7: =IF(B7="","",MAX(0,IFERROR(I7,0)*IFERROR(H7,0)-IFERROR(J7,0))) | M7: =IF(B7="","",MAX(0,K7-L7)) | N7: =IF(B7="","",IF(L7>=K7,"Paid",IF(L7>0,"Partial","Unpaid"))) | R7: =IF(B7="","",IFERROR(K7,0)+IFERROR(P7,0)-IFERROR(Q7,0)) | U7: =IF(B7="","",TRIM(LOWER(C7)&"|"&LOWER(D7)))
A8: =IF(B8="","",TEXT(ROW()-3,"""DC-""0000")) | K8: =IF(B8="","",MAX(0,IFERROR(I8,0)*IFERROR(H8,0)-IFERROR(J8,0))) | M8: =IF(B8="","",MAX(0,K8-L8)) | N8: =IF(B8="","",IF(L8>=K8,"Paid",IF(L8>0,"Partial","Unpaid"))) | R8: =IF(B8="","",IFERROR(K8,0)+IFERROR(P8,0)-IFERROR(Q8,0)) | U8: =IF(B8="","",TRIM(LOWER(C8)&"|"&LOWER(D8)))
A9: =IF(B9="","",TEXT(ROW()-3,"""DC-""0000")) | K9: =IF(B9="","",MAX(0,IFERROR(I9,0)*IFERROR(H9,0)-IFERROR(J9,0))) | M9: =IF(B9="","",MAX(0,K9-L9)) | N9: =IF(B9="","",IF(L9>=K9,"Paid",IF(L9>0,"Partial","Unpaid"))) | R9: =IF(B9="","",IFERROR(K9,0)+IFERROR(P9,0)-IFERROR(Q9,0)) | U9: =IF(B9="","",TRIM(LOWER(C9)&"|"&LOWER(D9)))
A10: =IF(B10="","",TEXT(ROW()-3,"""DC-""0000")) | K10: =IF(B10="","",MAX(0,IFERROR(I10,0)*IFERROR(H10,0)-IFERROR(J10,0))) | M10: =IF(B10="","",MAX(0,K10-L10)) | N10: =IF(B10="","",IF(L10>=K10,"Paid",IF(L10>0,"Partial","Unpaid"))) | R10: =IF(B10="","",IFERROR(K10,0)+IFERROR(P10,0)-IFERROR(Q10,0)) | U10: =IF(B10="","",TRIM(LOWER(C10)&"|"&LOWER(D10)))
A11: =IF(B11="","",TEXT(ROW()-3,"""DC-""0000")) | K11: =IF(B11="","",MAX(0,IFERROR(I11,0)*IFERROR(H11,0)-IFERROR(J11,0))) | M11: =IF(B11="","",MAX(0,K11-L11)) | N11: =IF(B11="","",IF(L11>=K11,"Paid",IF(L11>0,"Partial","Unpaid"))) | R11: =IF(B11="","",IFERROR(K11,0)+IFERROR(P11,0)-IFERROR(Q11,0)) | U11: =IF(B11="","",TRIM(LOWER(C11)&"|"&LOWER(D11)))
A12: =IF(B12="","",TEXT(ROW()-3,"""DC-""0000")) | K12: =IF(B12="","",MAX(0,IFERROR(I12,0)*IFERROR(H12,0)-IFERROR(J12,0))) | M12: =IF(B12="","",MAX(0,K12-L12)) | N12: =IF(B12="","",IF(L12>=K12,"Paid",IF(L12>0,"Partial","Unpaid"))) | R12: =IF(B12="","",IFERROR(K12,0)+IFERROR(P12,0)-IFERROR(Q12,0)) | U12: =IF(B12="","",TRIM(LOWER(C12)&"|"&LOWER(D12)))
A13: =IF(B13="","",TEXT(ROW()-3,"""DC-""0000")) | K13: =IF(B13="","",MAX(0,IFERROR(I13,0)*IFERROR(H13,0)-IFERROR(J13,0))) | M13: =IF(B13="","",MAX(0,K13-L13)) | N13: =IF(B13="","",IF(L13>=K13,"Paid",IF(L13>0,"Partial","Unpaid"))) | R13: =IF(B13="","",IFERROR(K13,0)+IFERROR(P13,0)-IFERROR(Q13,0)) | U13: =IF(B13="","",TRIM(LOWER(C13)&"|"&LOWER(D13)))
A14: =IF(B14="","",TEXT(ROW()-3,"""DC-""0000")) | K14: =IF(B14="","",MAX(0,IFERROR(I14,0)*IFERROR(H14,0)-IFERROR(J14,0))) | M14: =IF(B14="","",MAX(0,K14-L14)) | N14: =IF(B14="","",IF(L14>=K14,"Paid",IF(L14>0,"Partial","Unpaid"))) | R14: =IF(B14="","",IFERROR(K14,0)+IFERROR(P14,0)-IFERROR(Q14,0)) | U14: =IF(B14="","",TRIM(LOWER(C14)&"|"&LOWER(D14)))
A15: =IF(B15="","",TEXT(ROW()-3,"""DC-""0000")) | K15: =IF(B15="","",MAX(0,IFERROR(I15,0)*IFERROR(H15,0)-IFERROR(J15,0))) | M15: =IF(B15="","",MAX(0,K15-L15)) | N15: =IF(B15="","",IF(L15>=K15,"Paid",IF(L15>0,"Partial","Unpaid"))) | R15: =IF(B15="","",IFERROR(K15,0)+IFERROR(P15,0)-IFERROR(Q15,0)) | U15: =IF(B15="","",TRIM(LOWER(C15)&"|"&LOWER(D15)))
... A2003: =IF(B2003="","",TEXT(ROW()-3,"""DC-""0000")) | K2003: =IF(B2003="","",MAX(0,IFERROR(I2003,0)*IFERROR(H2003,0)-IFERROR(J2003,0))) | M2003: =IF(B2003="","",MAX(0,K2003-L2003)) | N2003: =IF(B2003="","",IF(L2003>=K2003,"Paid",IF(L2003>0,"Partial","Unpaid"))) | R2003: =IF(B2003="","",IFERROR(K2003,0)+IFERROR(P2003,0)-IFERROR(Q2003,0)) | U2003: =IF(B2003="","",TRIM(LOWER(C2003)&"|"&LOWER(D2003)))

Sheet Dashboard
A1: DEE CLEANERS — DASHBOARD
A2: KPIs are calculated live from the data sheets. Open the web application for the full dashboard with charts.
A3: KPI | B3: Value
A4: Today's Sales | B4: =SUMIFS(Orders!$L$4:$L$2003,Orders!$B$4:$B$2003,TODAY())
A5: Today's Orders | B5: =COUNTIF(Orders!$B$4:$B$2003,TODAY())
A6: Today's Expenses | B6: =SUMIFS(Expenses!$E$4:$E$2003,Expenses!$B$4:$B$2003,TODAY())
A7: Today's Profit | B7: =B4-B6
A8: Weekly Revenue | B8: =SUMIFS(Orders!$L$4:$L$2003,Orders!$B$4:$B$2003,">="&(TODAY()-6))
A9: Monthly Revenue | B9: =SUMIFS(Orders!$L$4:$L$2003,Orders!$B$4:$B$2003,">="&(EOMONTH(TODAY(),-1)+1))
A10: Outstanding Customer Payments | B10: =SUM(Orders!$M$4:$M$2003)
A11: Number of Active Customers | B11: =COUNTIF(Customers!$I$4:$I$1000,"Active")
A12: Active Househelps | B12: =COUNTIF(Househelps!$L$4:$L$500,"Placed")+COUNTIF(Househelps!$L$4:$L$500,"On Contract")
A13: Active Placements | B13: =COUNTIF(Placements!$J$4:$J$500,"Active")
A14: Pending Househelp Payments | B14: =COUNTIF('Househelp Payments'!$I$4:$I$500,"Pending")
A15: Active Contracts | B15: =COUNTIF(Contracts!$I$4:$I$500,"Active")
A16: Contracts Expiring Soon | B16: =COUNTIFS(Contracts!$F$4:$F$500,">="&TODAY(),Contracts!$F$4:$F$500,"<="&(TODAY()+30),Contracts!$I$4:$I$500,"Active")
A17: Open Complaints | B17: =COUNTIF(Complaints!$J$4:$J$500,"Reported")+COUNTIF(Complaints!$J$4:$J$500,"Under Review")+COUNTIF(Complaints!$J$4:$J$500,"Mediation")
A18: Replacement Requests | B18: =COUNTIF(Replacements!$I$4:$I$500,"Requested")+COUNTIF(Replacements!$I$4:$I$500,"In Progress")
A20: Charts (revenue, orders, payments, househelp, contracts) are rendered in the Dee Cleaners web application.

Sheet Customers
A1: DEE CLEANERS — CUSTOMERS
A2: Use the app to add and edit records. IDs are assigned automatically.
A3: Customer Name | B3: Phone | C3: Email | D3: Number of Orders | E3: Total Spending | F3: Total Paid | G3: Outstanding Balance | H3: Last Service Date | I3: Customer Status

Sheet Expenses
A1: DEE CLEANERS — EXPENSES
A2: Use the app to add and edit records. IDs are assigned automatically.
A3: Expense ID | B3: Date | C3: Category | D3: Description | E3: Amount | F3: Payment Method | G3: Related Service | H3: Notes

Sheet Payments
A1: DEE CLEANERS — PAYMENTS
A2: Use the app to add and edit records. IDs are assigned automatically.
A3: Payment ID | B3: Date | C3: Customer | D3: Order ID | E3: Amount | F3: Payment Method | G3: Reference | H3: Received By | I3: Notes

Sheet Househelps
A1: DEE CLEANERS — HOUSEHELPS
A2: Use the app to add and edit records. IDs are assigned automatically.
A3: Househelp ID | B3: Full Name | C3: Phone | D3: Email | E3: Gender | F3: Nationality | G3: Occupation | H3: NIDA Number | I3: City/Country | J3: Home Address | K3: Registration Date | L3: Status | M3: Skills | N3: Experience | O3: Availability | P3: Notes

Sheet Employers
A1: DEE CLEANERS — EMPLOYERS
A2: Use the app to add and edit records. IDs are assigned automatically.
A3: Client ID | B3: Full Name | C3: Family Member/Relative | D3: Phone | E3: Email | F3: Gender | G3: Nationality | H3: Occupation | I3: City/Country | J3: NIDA Number | K3: Home Address | L3: Registration Date | M3: Notes

Sheet Placements
A1: DEE CLEANERS — PLACEMENTS
A2: Use the app to add and edit records. IDs are assigned automatically.
A3: Placement ID | B3: Househelp ID | C3: Employer ID | D3: Category | E3: Job Description | F3: Salary | G3: Payment Frequency | H3: Start Date | I3: Expected End Date | J3: Status | K3: Contract Status | L3: Live-in/Live-out | M3: Working Hours | N3: Accommodation | O3: Meals | P3: Agency Fee | Q3: Notes

Sheet Househelp Payments
A1: DEE CLEANERS — HOUSEHELP PAYMENTS
A2: Use the app to add and edit records. IDs are assigned automatically.
A3: Payment ID | B3: Househelp ID | C3: Employer ID | D3: Placement ID | E3: Payment Date | F3: Period | G3: Amount | H3: Payment Method | I3: Status | J3: Reference | K3: Notes

Sheet Contracts
A1: DEE CLEANERS — CONTRACTS
A2: Use the app to add and edit records. IDs are assigned automatically.
A3: Contract ID | B3: Placement ID | C3: Employer | D3: Househelp | E3: Start Date | F3: End Date | G3: Minimum Duration | H3: Notice Required | I3: Contract Status | J3: Termination Date | K3: Termination Reason | L3: Document Link | M3: Employer Signature | N3: Househelp Signature | O3: Dee Cleaners Acknowledged | P3: Notes

Sheet Complaints
A1: DEE CLEANERS — COMPLAINTS
A2: Use the app to add and edit records. IDs are assigned automatically.
A3: Complaint ID | B3: Date | C3: Client | D3: Househelp | E3: Placement | F3: Complaint Type | G3: Description | H3: Reported By | I3: Severity | J3: Status | K3: Dee Cleaners Action | L3: Resolution | M3: Resolution Date | N3: Notes

Sheet Replacements
A1: DEE CLEANERS — REPLACEMENTS
A2: Use the app to add and edit records. IDs are assigned automatically.
A3: Replacement ID | B3: Original Placement | C3: Original Househelp | D3: Employer | E3: Reason | F3: Request Date | G3: Replacement Househelp | H3: Replacement Date | I3: Status | J3: Notes

Sheet Attendance
A1: DEE CLEANERS — ATTENDANCE
A2: Use the app to add and edit records. IDs are assigned automatically.
A3: Attendance ID | B3: Date | C3: Person Type | D3: Person | E3: Check In | F3: Check Out | G3: Hours | H3: Status | I3: Notes

Sheet Archive
A1: DEE CLEANERS — ARCHIVED (DELETED) ORDERS
A2: Deleted orders are moved here — they are never permanently removed. Google Sheets is the single source of truth.
A3: Order ID | B3: Date | C3: Customer Name | D3: Phone | E3: Email | F3: Service | G3: Description | H3: Quantity | I3: Unit Price | J3: Discount | K3: Total* | L3: Amount Paid | M3: Balance* | N3: Payment Status* | O3: Order Status | P3: Transport Fee | Q3: Direct Expense | R3: Net Service Profit* | S3: Notes | T3: Line Items JSON | U3: Unique Customer Helper* | V3: Archived Date
